2021-02-24 15:53:45,914 INFO    MainThread:7828 [internal.py:wandb_internal():81] W&B internal server running at pid: 7828
2021-02-24 15:53:45,916 INFO    WriterThread:7828 [datastore.py:open_for_write():77] open: C:\Users\Juhyeon\Desktop\repository\Proxy-Anchor-CVPR2020\code\wandb\run-20210224_155344-2rxeumoe\run-2rxeumoe.wandb
2021-02-24 15:53:45,916 DEBUG   HandlerThread:7828 [handler.py:handle_request():93] handle_request: check_version
2021-02-24 15:53:45,917 DEBUG   SenderThread:7828 [sender.py:send():117] send: header
2021-02-24 15:53:45,917 DEBUG   SenderThread:7828 [sender.py:send():117] send: request
2021-02-24 15:53:45,918 DEBUG   SenderThread:7828 [sender.py:send_request():126] send_request: check_version
2021-02-24 15:53:45,919 DEBUG   Thread-8  :7828 [connectionpool.py:_new_conn():824] Starting new HTTPS connection (1): pypi.org
2021-02-24 15:53:46,095 DEBUG   Thread-8  :7828 [connectionpool.py:_make_request():396] https://pypi.org:443 "GET /pypi/wandb/json HTTP/1.1" 200 54531
2021-02-24 15:53:46,137 DEBUG   SenderThread:7828 [sender.py:send():117] send: run
2021-02-24 15:53:46,150 DEBUG   SenderThread:7828 [util.py:is_cygwin_git():315] Failed checking if running in CYGWIN due to: FileNotFoundError(2, '지정된 파일을 찾을 수 없습니다', None, 2, None)
2021-02-24 15:53:46,154 DEBUG   SenderThread:7828 [cmd.py:execute():719] Popen(['git', 'cat-file', '--batch-check'], cwd=C:\Users\Juhyeon\Desktop\repository\Proxy-Anchor-CVPR2020, universal_newlines=False, shell=None, istream=<valid stream>)
2021-02-24 15:53:46,205 DEBUG   SenderThread:7828 [connectionpool.py:_new_conn():824] Starting new HTTPS connection (1): api.wandb.ai
2021-02-24 15:53:57,315 DEBUG   SenderThread:7828 [connectionpool.py:_new_conn():824] Starting new HTTPS connection (1): api.wandb.ai
2021-02-24 15:54:09,561 DEBUG   SenderThread:7828 [connectionpool.py:_new_conn():824] Starting new HTTPS connection (1): api.wandb.ai
2021-02-24 15:54:16,138 DEBUG   HandlerThread:7828 [handler.py:handle_request():93] handle_request: shutdown
2021-02-24 15:54:16,138 INFO    HandlerThread:7828 [handler.py:finish():312] shutting down handler
2021-02-24 15:54:16,144 INFO    WriterThread:7828 [datastore.py:close():258] close: C:\Users\Juhyeon\Desktop\repository\Proxy-Anchor-CVPR2020\code\wandb\run-20210224_155344-2rxeumoe\run-2rxeumoe.wandb
2021-02-24 15:54:19,582 ERROR   SenderThread:7828 [retry.py:__call__():111] Retry attempt failed:
Traceback (most recent call last):
  File "C:\Users\Juhyeon\anaconda3\envs\torch17\lib\site-packages\urllib3\connectionpool.py", line 387, in _make_request
    six.raise_from(e, None)
  File "<string>", line 2, in raise_from
  File "C:\Users\Juhyeon\anaconda3\envs\torch17\lib\site-packages\urllib3\connectionpool.py", line 383, in _make_request
    httplib_response = conn.getresponse()
  File "C:\Users\Juhyeon\anaconda3\envs\torch17\lib\http\client.py", line 1354, in getresponse
    response.begin()
  File "C:\Users\Juhyeon\anaconda3\envs\torch17\lib\http\client.py", line 307, in begin
    version, status, reason = self._read_status()
  File "C:\Users\Juhyeon\anaconda3\envs\torch17\lib\http\client.py", line 268, in _read_status
    line = str(self.fp.readline(_MAXLINE + 1), "iso-8859-1")
  File "C:\Users\Juhyeon\anaconda3\envs\torch17\lib\socket.py", line 586, in readinto
    return self._sock.recv_into(b)
  File "C:\Users\Juhyeon\anaconda3\envs\torch17\lib\site-packages\urllib3\contrib\pyopenssl.py", line 294, in recv_into
    raise timeout('The read operation timed out')
socket.timeout: The read operation timed out

During handling of the above exception, another exception occurred:

Traceback (most recent call last):
  File "C:\Users\Juhyeon\anaconda3\envs\torch17\lib\site-packages\requests\adapters.py", line 440, in send
    timeout=timeout
  File "C:\Users\Juhyeon\anaconda3\envs\torch17\lib\site-packages\urllib3\connectionpool.py", line 639, in urlopen
    _stacktrace=sys.exc_info()[2])
  File "C:\Users\Juhyeon\anaconda3\envs\torch17\lib\site-packages\urllib3\util\retry.py", line 357, in increment
    raise six.reraise(type(error), error, _stacktrace)
  File "C:\Users\Juhyeon\anaconda3\envs\torch17\lib\site-packages\urllib3\packages\six.py", line 686, in reraise
    raise value
  File "C:\Users\Juhyeon\anaconda3\envs\torch17\lib\site-packages\urllib3\connectionpool.py", line 601, in urlopen
    chunked=chunked)
  File "C:\Users\Juhyeon\anaconda3\envs\torch17\lib\site-packages\urllib3\connectionpool.py", line 389, in _make_request
    self._raise_timeout(err=e, url=url, timeout_value=read_timeout)
  File "C:\Users\Juhyeon\anaconda3\envs\torch17\lib\site-packages\urllib3\connectionpool.py", line 309, in _raise_timeout
    raise ReadTimeoutError(self, url, "Read timed out. (read timeout=%s)" % timeout_value)
urllib3.exceptions.ReadTimeoutError: HTTPSConnectionPool(host='api.wandb.ai', port=443): Read timed out. (read timeout=10)

During handling of the above exception, another exception occurred:

Traceback (most recent call last):
  File "C:\Users\Juhyeon\anaconda3\envs\torch17\lib\site-packages\wandb\old\retry.py", line 96, in __call__
    result = self._call_fn(*args, **kwargs)
  File "C:\Users\Juhyeon\anaconda3\envs\torch17\lib\site-packages\wandb\sdk\internal\internal_api.py", line 123, in execute
    return self.client.execute(*args, **kwargs)
  File "C:\Users\Juhyeon\anaconda3\envs\torch17\lib\site-packages\wandb\vendor\gql-0.2.0\gql\client.py", line 52, in execute
    result = self._get_result(document, *args, **kwargs)
  File "C:\Users\Juhyeon\anaconda3\envs\torch17\lib\site-packages\wandb\vendor\gql-0.2.0\gql\client.py", line 60, in _get_result
    return self.transport.execute(document, *args, **kwargs)
  File "C:\Users\Juhyeon\anaconda3\envs\torch17\lib\site-packages\wandb\vendor\gql-0.2.0\gql\transport\requests.py", line 38, in execute
    request = requests.post(self.url, **post_args)
  File "C:\Users\Juhyeon\anaconda3\envs\torch17\lib\site-packages\requests\api.py", line 112, in post
    return request('post', url, data=data, json=json, **kwargs)
  File "C:\Users\Juhyeon\anaconda3\envs\torch17\lib\site-packages\requests\api.py", line 58, in request
    return session.request(method=method, url=url, **kwargs)
  File "C:\Users\Juhyeon\anaconda3\envs\torch17\lib\site-packages\requests\sessions.py", line 508, in request
    resp = self.send(prep, **send_kwargs)
  File "C:\Users\Juhyeon\anaconda3\envs\torch17\lib\site-packages\requests\sessions.py", line 618, in send
    r = adapter.send(request, **kwargs)
  File "C:\Users\Juhyeon\anaconda3\envs\torch17\lib\site-packages\requests\adapters.py", line 521, in send
    raise ReadTimeout(e, request=request)
requests.exceptions.ReadTimeout: HTTPSConnectionPool(host='api.wandb.ai', port=443): Read timed out. (read timeout=10)
2021-02-24 15:54:24,210 DEBUG   SenderThread:7828 [connectionpool.py:_new_conn():824] Starting new HTTPS connection (1): api.wandb.ai
